Workbook

Sheet RiderExperience
A1: route_short_name | B1: route_long_name | C1: first_bus_departure | D1: last_bus_arrival_excel_ready | E1: service_span_hours | F1: total_daily_trips | G1: avg_wait_time_minutes
A2: 099 | B2: Commercial-Broadway/UBC (B-Line) | C2: 0.22916667 | D2: 0.14513889 | E2: 22 | F2: 451 | G2: 2.9
A3: R4 | B3: 41st Ave | C3: 0.20833333 | D3: 0.066666667 | E3: 20.6 | F3: 384 | G3: 3.2
A4: 049 | B4: Metrotown Station/Dunbar Loop/UBC | C4: 0.22708333 | D4: 0.04375 | E4: 19.6 | F4: 328 | G4: 3.6
A5: 245 | B5: Phibbs/Capilano | C5: 0.23819444 | D5: 0.070138889 | E5: 20 | F5: 267 | G5: 4.5
A6: R5 | B6: Hastings St | C6: 0.20277778 | D6: 0.091666667 | E6: 21.3 | F6: 258 | G6: 5
A7: R6 | B7: Scott Rd | C7: 0.18680556 | D7: 0.066666667 | E7: 21.1 | F7: 258 | G7: 4.9
A8: 005 | B8: Robson/Downtown | C8: 0.22222222 | D8: 0.09162037 | E8: 20.9 | F8: 250 | G8: 5
A9: 006 | B9: Davie/Downtown | C9: 0.22291667 | D9: 0.085416667 | E9: 20.7 | F9: 250 | G9: 5
A10: 130 | B10: Metrotown/Phibbs Exchange | C10: 0.22569444 | D10: 0.079166667 | E10: 20.5 | F10: 247 | G10: 5
A11: 323 | B11: Newton Exchange/Surrey Central Station | C11: 0.18541667 | D11: 0.10208333 | E11: 22 | F11: 242 | G11: 5.5
A12: 009 | B12: Boundary/Commercial-Broadway/UBC | C12: 0.19236111 | D12: 0.11799769 | E12: 22.2 | F12: 239 | G12: 5.6
A13: 250 | B13: Horseshoe Bay/Dundarave/Vancouver | C13: 0.21875 | D13: 0.073611111 | E13: 20.5 | F13: 238 | G13: 5.2
... A206: 509 | B206: Walnut Grove/Surrey Central Station | C206: 0.225 | D206: 0.79027778 | E206: 13.6 | F206: 17 | G206: 47.9
A207: N35 | B207: Downtown/SFU NightBus | D207: 0.24722222 | E207: 5 | F207: 17 | G207: 17.6
A208: N20 | B208: Downtown/Victoria NightBus | D208: 0.24652778 | E208: 4.7 | F208: 16 | G208: 17.4
A209: 354 | B209: White Rock South/Bridgeport Station | C209: 0.21458333 | D209: 0.79583333 | E209: 14 | F209: 15 | G209: 55.8
A210: 749 | B210: Ruskin/Haney Place | C210: 0.28402778 | D210: 0.83333333 | E210: 13.2 | F210: 15 | G210: 52.7
A211: N8 | B211: Downtown/Fraser NightBus | D211: 0.24027778 | E211: 4.3 | F211: 15 | G211: 17.1
A212: 748 | B212: Thornhill/Haney Place | C212: 0.23958333 | D212: 0.81180556 | E212: 13.7 | F212: 14 | G212: 58.9
A213: N10 | B213: Downtown/Richmond NightBus | D213: 0.23194444 | E213: 4.3 | F213: 13 | G213: 19.9
A214: 393 | B214: Newton Exchange/Surrey Central Station | C214: 0.24375 | D214: 0.81666667 | E214: 13.8 | F214: 12 | G214: 68.8
A215: 608 | B215: Ladner Ring | C215: 0.23263889 | D215: 0.32986111 | E215: 2.3 | F215: 12 | G215: 11.7
A216: N19 | B216: Downtown/Surrey Central Station NightBus | D216: 0.23611111 | E216: 4.8 | F216: 11 | G216: 26.4
A217: 231 | B217: Harbourside/Lonsdale Quay | C217: 0.30555556 | D217: 0.74722222 | E217: 10.6 | F217: 10 | G217: 63.6
A218: 247 | B218: Grouse Mountain/Downtown | C218: 0.26805556 | D218: 0.78819444 | E218: 12.5 | F218: 10 | G218: 74.9
A219: 391 | B219: Scottsdale/Scott Road Station | C219: 0.22222222 | D219: 0.77708333 | E219: 13.3 | F219: 10 | G219: 79.9
A220: 606 | B220: Ladner Ring | C220: 0.69444444 | D220: 0.80763889 | E220: 2.7 | F220: 10 | G220: 16.3
A221: N24 | B221: Downtown/Lynn Valley NightBus | D221: 0.175 | E221: 3.2 | F221: 9 | G221: 21.4
A222: N17 | B222: Downtown/UBC NightBus | D222: 0.15625 | E222: 2.1 | F222: 7 | G222: 18
A223: N15 | B223: Downtown/Cambie NightBus | D223: 0.15069444 | E223: 1.9 | F223: 6 | G223: 18.8
A224: N22 | B224: Downtown/Macdonald NightBus | D224: 0.15069444 | E224: 2 | F224: 6 | G224: 19.5

Sheet Advanced_Metrics
A1: route_short_name | B1: direction_id | C1: trip_headsign | D1: num_stops | E1: total_trips | F1: trips_peak_am | G1: trips_midday | H1: trips_peak_pm | K1: trip peak_am | L1: trips midday | M1: trips peak_pm
A2: 002 | B2: 0 | C2: 2 Macdonald/To Burrard Station | D2: 2 | E2: 103 | F2: =advaced_metrics__2[[#This Row],[total_trips]]-(advaced_metrics__2[[#This Row],[trips_midday]]+advaced_metrics__2[[#This Row],[trips_peak_pm]]) -> 69 | G2: 16 | H2: 18 | J2: {=_xlfn.UNIQUE(advaced_metrics__2[route_short_name])} -> 002 | K2: =SUMIFS(advaced_metrics__2[trips_peak_am],advaced_metrics__2[route_short_name],J2) -> 136 | L2: =SUMIFS(advaced_metrics__2[trips_midday],advaced_metrics__2[route_short_name],J2) -> 31 | M2: =SUMIFS(advaced_metrics__2[trips_peak_pm],advaced_metrics__2[route_short_name],J2) -> 38
A3: 002 | B3: 1 | C3: 2 Macdonald/To 16th Avenue | D3: 1 | E3: 30 | F3: =advaced_metrics__2[[#This Row],[total_trips]]-(advaced_metrics__2[[#This Row],[trips_midday]]+advaced_metrics__2[[#This Row],[trips_peak_pm]]) -> 19 | G3: 7 | H3: 4 | J3: 003 | K3: =SUMIFS(advaced_metrics__2[trips_peak_am],advaced_metrics__2[route_short_name],J3) -> 118 | L3: =SUMIFS(advaced_metrics__2[trips_midday],advaced_metrics__2[route_short_name],J3) -> 25 | M3: =SUMIFS(advaced_metrics__2[trips_peak_pm],advaced_metrics__2[route_short_name],J3) -> 27
A4: 002 | B4: 1 | C4: 2 Macdonald/To Dunbar Loop | D4: 1 | E4: 72 | F4: =advaced_metrics__2[[#This Row],[total_trips]]-(advaced_metrics__2[[#This Row],[trips_midday]]+advaced_metrics__2[[#This Row],[trips_peak_pm]]) -> 48 | G4: 8 | H4: 16 | J4: 004 | K4: =SUMIFS(advaced_metrics__2[trips_peak_am],advaced_metrics__2[route_short_name],J4) -> 76 | L4: =SUMIFS(advaced_metrics__2[trips_midday],advaced_metrics__2[route_short_name],J4) -> 24 | M4: =SUMIFS(advaced_metrics__2[trips_peak_pm],advaced_metrics__2[route_short_name],J4) -> 30
A5: 003 | B5: 0 | C5: 3 Main/To Waterfront Station | D5: 1 | E5: 85 | F5: =advaced_metrics__2[[#This Row],[total_trips]]-(advaced_metrics__2[[#This Row],[trips_midday]]+advaced_metrics__2[[#This Row],[trips_peak_pm]]) -> 59 | G5: 13 | H5: 13 | J5: 005 | K5: =SUMIFS(advaced_metrics__2[trips_peak_am],advaced_metrics__2[route_short_name],J5) -> 158 | L5: =SUMIFS(advaced_metrics__2[trips_midday],advaced_metrics__2[route_short_name],J5) -> 31 | M5: =SUMIFS(advaced_metrics__2[trips_peak_pm],advaced_metrics__2[route_short_name],J5) -> 61
A6: 003 | B6: 1 | C6: 3 Main/To Marine Dr Station | D6: 1 | E6: 85 | F6: =advaced_metrics__2[[#This Row],[total_trips]]-(advaced_metrics__2[[#This Row],[trips_midday]]+advaced_metrics__2[[#This Row],[trips_peak_pm]]) -> 59 | G6: 12 | H6: 14 | J6: 006 | K6: =SUMIFS(advaced_metrics__2[trips_peak_am],advaced_metrics__2[route_short_name],J6) -> 156 | L6: =SUMIFS(advaced_metrics__2[trips_midday],advaced_metrics__2[route_short_name],J6) -> 33 | M6: =SUMIFS(advaced_metrics__2[trips_peak_pm],advaced_metrics__2[route_short_name],J6) -> 61
A7: 004 | B7: 0 | C7: 4 Downtown | D7: 1 | E7: 3 | F7: =advaced_metrics__2[[#This Row],[total_trips]]-(advaced_metrics__2[[#This Row],[trips_midday]]+advaced_metrics__2[[#This Row],[trips_peak_pm]]) -> 3 | G7: 0 | H7: 0 | J7: 007 | K7: =SUMIFS(advaced_metrics__2[trips_peak_am],advaced_metrics__2[route_short_name],J7) -> 79 | L7: =SUMIFS(advaced_metrics__2[trips_midday],advaced_metrics__2[route_short_name],J7) -> 24 | M7: =SUMIFS(advaced_metrics__2[trips_peak_pm],advaced_metrics__2[route_short_name],J7) -> 23
A8: 004 | B8: 0 | C8: 4 Powell | D8: 3 | E8: 66 | F8: =advaced_metrics__2[[#This Row],[total_trips]]-(advaced_metrics__2[[#This Row],[trips_midday]]+advaced_metrics__2[[#This Row],[trips_peak_pm]]) -> 38 | G8: 12 | H8: 16 | J8: 008 | K8: =SUMIFS(advaced_metrics__2[trips_peak_am],advaced_metrics__2[route_short_name],J8) -> 122 | L8: =SUMIFS(advaced_metrics__2[trips_midday],advaced_metrics__2[route_short_name],J8) -> 25 | M8: =SUMIFS(advaced_metrics__2[trips_peak_pm],advaced_metrics__2[route_short_name],J8) -> 24
A9: 004 | B9: 1 | C9: 4 To Blanca Loop | D9: 1 | E9: 2 | F9: =advaced_metrics__2[[#This Row],[total_trips]]-(advaced_metrics__2[[#This Row],[trips_midday]]+advaced_metrics__2[[#This Row],[trips_peak_pm]]) -> 2 | G9: 0 | H9: 0 | J9: 009 | K9: =SUMIFS(advaced_metrics__2[trips_peak_am],advaced_metrics__2[route_short_name],J9) -> 166 | L9: =SUMIFS(advaced_metrics__2[trips_midday],advaced_metrics__2[route_short_name],J9) -> 32 | M9: =SUMIFS(advaced_metrics__2[trips_peak_pm],advaced_metrics__2[route_short_name],J9) -> 41
A10: 004 | B10: 1 | C10: 4 UBC | D10: 1 | E10: 59 | F10: =advaced_metrics__2[[#This Row],[total_trips]]-(advaced_metrics__2[[#This Row],[trips_midday]]+advaced_metrics__2[[#This Row],[trips_peak_pm]]) -> 33 | G10: 12 | H10: 14 | J10: 010 | K10: =SUMIFS(advaced_metrics__2[trips_peak_am],advaced_metrics__2[route_short_name],J10) -> 102 | L10: =SUMIFS(advaced_metrics__2[trips_midday],advaced_metrics__2[route_short_name],J10) -> 24 | M10: =SUMIFS(advaced_metrics__2[trips_peak_pm],advaced_metrics__2[route_short_name],J10) -> 27
A11: 005 | B11: 0 | C11: 5 Downtown | D11: 1 | E11: 124 | F11: =advaced_metrics__2[[#This Row],[total_trips]]-(advaced_metrics__2[[#This Row],[trips_midday]]+advaced_metrics__2[[#This Row],[trips_peak_pm]]) -> 78 | G11: 15 | H11: 31 | J11: 014 | K11: =SUMIFS(advaced_metrics__2[trips_peak_am],advaced_metrics__2[route_short_name],J11) -> 94 | L11: =SUMIFS(advaced_metrics__2[trips_midday],advaced_metrics__2[route_short_name],J11) -> 24 | M11: =SUMIFS(advaced_metrics__2[trips_peak_pm],advaced_metrics__2[route_short_name],J11) -> 31
A12: 005 | B12: 0 | C12: 5 To Granville | D12: 1 | E12: 2 | F12: =advaced_metrics__2[[#This Row],[total_trips]]-(advaced_metrics__2[[#This Row],[trips_midday]]+advaced_metrics__2[[#This Row],[trips_peak_pm]]) -> 2 | G12: 0 | H12: 0 | J12: 015 | K12: =SUMIFS(advaced_metrics__2[trips_peak_am],advaced_metrics__2[route_short_name],J12) -> 95 | L12: =SUMIFS(advaced_metrics__2[trips_midday],advaced_metrics__2[route_short_name],J12) -> 23 | M12: =SUMIFS(advaced_metrics__2[trips_peak_pm],advaced_metrics__2[route_short_name],J12) -> 23
A13: 005 | B13: 1 | C13: 5 Robson | D13: 2 | E13: 124 | F13: =advaced_metrics__2[[#This Row],[total_trips]]-(advaced_metrics__2[[#This Row],[trips_midday]]+advaced_metrics__2[[#This Row],[trips_peak_pm]]) -> 78 | G13: 16 | H13: 30 | J13: 016 | K13: =SUMIFS(advaced_metrics__2[trips_peak_am],advaced_metrics__2[route_short_name],J13) -> 107 | L13: =SUMIFS(advaced_metrics__2[trips_midday],advaced_metrics__2[route_short_name],J13) -> 30 | M13: =SUMIFS(advaced_metrics__2[trips_peak_pm],advaced_metrics__2[route_short_name],J13) -> 36
A14: 006 | B14: 0 | C14: 6 Downtown | D14: 1 | E14: 124 | F14: =advaced_metrics__2[[#This Row],[total_trips]]-(advaced_metrics__2[[#This Row],[trips_midday]]+advaced_metrics__2[[#This Row],[trips_peak_pm]]) -> 77 | G14: 16 | H14: 31 | J14: 017 | K14: =SUMIFS(advaced_metrics__2[trips_peak_am],advaced_metrics__2[route_short_name],J14) -> 87 | L14: =SUMIFS(advaced_metrics__2[trips_midday],advaced_metrics__2[route_short_name],J14) -> 24 | M14: =SUMIFS(advaced_metrics__2[trips_peak_pm],advaced_metrics__2[route_short_name],J14) -> 24
... A224: 210 | B224: 0 | C224: 210 Mountain Hwy Exp/To Upper Lynn Valley | D224: 2 | E224: 45 | F224: =advaced_metrics__2[[#This Row],[total_trips]]-(advaced_metrics__2[[#This Row],[trips_midday]]+advaced_metrics__2[[#This Row],[trips_peak_pm]]) -> 28 | G224: 6 | H224: 11 | J224: R6 | K224: =SUMIFS(advaced_metrics__2[trips_peak_am],advaced_metrics__2[route_short_name],J224) -> 178 | L224: =SUMIFS(advaced_metrics__2[trips_midday],advaced_metrics__2[route_short_name],J224) -> 35 | M224: =SUMIFS(advaced_metrics__2[trips_peak_pm],advaced_metrics__2[route_short_name],J224) -> 45
A225: 210 | B225: 1 | C225: 210 Mountain Hwy Exp/To Burrard Station | D225: 1 | E225: 42 | F225: =advaced_metrics__2[[#This Row],[total_trips]]-(advaced_metrics__2[[#This Row],[trips_midday]]+advaced_metrics__2[[#This Row],[trips_peak_pm]]) -> 27 | G225: 6 | H225: 9
A226: 210 | B226: 1 | C226: 210 Mountain Hwy Exp/To Phibbs Exchange | D226: 1 | E226: 1 | F226: =advaced_metrics__2[[#This Row],[total_trips]]-(advaced_metrics__2[[#This Row],[trips_midday]]+advaced_metrics__2[[#This Row],[trips_peak_pm]]) -> 0 | G226: 0 | H226: 1
A227: 211 | B227: 0 | C227: 211 Seymour | D227: 2 | E227: 38 | F227: =advaced_metrics__2[[#This Row],[total_trips]]-(advaced_metrics__2[[#This Row],[trips_midday]]+advaced_metrics__2[[#This Row],[trips_peak_pm]]) -> 25 | G227: 6 | H227: 7
A228: 211 | B228: 0 | C228: 211 Seymour via Dollarton | D228: 2 | E228: 5 | F228: =advaced_metrics__2[[#This Row],[total_trips]]-(advaced_metrics__2[[#This Row],[trips_midday]]+advaced_metrics__2[[#This Row],[trips_peak_pm]]) -> 5 | G228: 0 | H228: 0
A229: 211 | B229: 1 | C229: 211 Burrard Station | D229: 1 | E229: 29 | F229: =advaced_metrics__2[[#This Row],[total_trips]]-(advaced_metrics__2[[#This Row],[trips_midday]]+advaced_metrics__2[[#This Row],[trips_peak_pm]]) -> 19 | G229: 6 | H229: 4
A230: 211 | B230: 1 | C230: 211 Phibbs Exchange | D230: 1 | E230: 17 | F230: =advaced_metrics__2[[#This Row],[total_trips]]-(advaced_metrics__2[[#This Row],[trips_midday]]+advaced_metrics__2[[#This Row],[trips_peak_pm]]) -> 14 | G230: 0 | H230: 3
A231: 212 | B231: 0 | C231: 212 Dollarton Hwy/To Deep Cove | D231: 1 | E231: 34 | F231: =advaced_metrics__2[[#This Row],[total_trips]]-(advaced_metrics__2[[#This Row],[trips_midday]]+advaced_metrics__2[[#This Row],[trips_peak_pm]]) -> 22 | G231: 6 | H231: 6
A232: 212 | B232: 1 | C232: 212 Dollarton Hwy/To Phibbs Exchange | D232: 2 | E232: 37 | F232: =advaced_metrics__2[[#This Row],[total_trips]]-(advaced_metrics__2[[#This Row],[trips_midday]]+advaced_metrics__2[[#This Row],[trips_peak_pm]]) -> 24 | G232: 6 | H232: 7
A233: 214 | B233: 0 | C233: 214 Blueridge | D233: 2 | E233: 37 | F233: =advaced_metrics__2[[#This Row],[total_trips]]-(advaced_metrics__2[[#This Row],[trips_midday]]+advaced_metrics__2[[#This Row],[trips_peak_pm]]) -> 24 | G233: 6 | H233: 7
A234: 214 | B234: 1 | C234: 214 Burrard Station | D234: 1 | E234: 5 | F234: =advaced_metrics__2[[#This Row],[total_trips]]-(advaced_metrics__2[[#This Row],[trips_midday]]+advaced_metrics__2[[#This Row],[trips_peak_pm]]) -> 5 | G234: 0 | H234: 0
A235: 214 | B235: 1 | C235: 214 Phibbs Exchange | D235: 1 | E235: 33 | F235: =advaced_metrics__2[[#This Row],[total_trips]]-(advaced_metrics__2[[#This Row],[trips_midday]]+advaced_metrics__2[[#This Row],[trips_peak_pm]]) -> 20 | G235: 6 | H235: 7
A236: 215 | B236: 0 | C236: 215 Indian River | D236: 1 | E236: 43 | F236: =advaced_metrics__2[[#This Row],[total_trips]]-(advaced_metrics__2[[#This Row],[trips_midday]]+advaced_metrics__2[[#This Row],[trips_peak_pm]]) -> 26 | G236: 6 | H236: 11
... A568: R6 | B568: 1 | C568: R6 Scott Road/To Newton Exchange | D568: 1 | E568: 128 | F568: =advaced_metrics__2[[#This Row],[total_trips]]-(advaced_metrics__2[[#This Row],[trips_midday]]+advaced_metrics__2[[#This Row],[trips_peak_pm]]) -> 87 | G568: 18 | H568: 23

Sheet Route_map
A1: route_label | B1: direction_id | C1: stop_sequence | D1: stop_name | E1: stop_lat | F1: stop_lon | G1: Distance
A2: 002 | B2: 0 | C2: 1 | D2: Dunbar Loop @ Bay 2 | E2: 49.234661 | F2: -123.18576 | G2: =IF(route_map__2[[#This Row],[route_label]]<>A3,0,SQRT((E3-route_map__2[[#This Row],[stop_lat]])^2 + ((F3-route_map__2[[#This Row],[stop_lon]])*COS(RADIANS(route_map__2[[#This Row],[stop_lat]])))^2)*111.32) -> 0.30342679
A3: 002 | B3: 0 | C3: 2 | D3: Eastbound W 41 Ave @ Collingwood St | E3: 49.234698 | F3: -123.18158 | G3: =IF(route_map__2[[#This Row],[route_label]]<>A4,0,SQRT((E4-route_map__2[[#This Row],[stop_lat]])^2 + ((F4-route_map__2[[#This Row],[stop_lon]])*COS(RADIANS(route_map__2[[#This Row],[stop_lat]])))^2)*111.32) -> 0.23841588
A4: 002 | B4: 0 | C4: 3 | D4: Eastbound W 41 Ave @ Blenheim St | E4: 49.234696 | F4: -123.1783 | G4: =IF(route_map__2[[#This Row],[route_label]]<>A5,0,SQRT((E5-route_map__2[[#This Row],[stop_lat]])^2 + ((F5-route_map__2[[#This Row],[stop_lon]])*COS(RADIANS(route_map__2[[#This Row],[stop_lat]])))^2)*111.32) -> 0.34949463
A5: 002 | B5: 0 | C5: 4 | D5: Eastbound W 41 Ave @ Carnarvon St | E5: 49.23467 | F5: -123.1735 | G5: =IF(route_map__2[[#This Row],[route_label]]<>A6,0,SQRT((E6-route_map__2[[#This Row],[stop_lat]])^2 + ((F6-route_map__2[[#This Row],[stop_lon]])*COS(RADIANS(route_map__2[[#This Row],[stop_lat]])))^2)*111.32) -> 0.43451483
A6: 002 | B6: 0 | C6: 5 | D6: Northbound Mackenzie St @ W 38 Ave | E6: 49.237919 | F6: -123.17018 | G6: =IF(route_map__2[[#This Row],[route_label]]<>A7,0,SQRT((E7-route_map__2[[#This Row],[stop_lat]])^2 + ((F7-route_map__2[[#This Row],[stop_lon]])*COS(RADIANS(route_map__2[[#This Row],[stop_lat]])))^2)*111.32) -> 0.41455798
A7: 002 | B7: 0 | C7: 6 | D7: Northbound Mackenzie St @ W 34 Ave | E7: 49.241643 | F7: -123.17016 | G7: =IF(route_map__2[[#This Row],[route_label]]<>A8,0,SQRT((E8-route_map__2[[#This Row],[stop_lat]])^2 + ((F8-route_map__2[[#This Row],[stop_lon]])*COS(RADIANS(route_map__2[[#This Row],[stop_lat]])))^2)*111.32) -> 0.43461035
A8: 002 | B8: 0 | C8: 7 | D8: Northbound Mackenzie St @ W 30 Ave | E8: 49.245547 | F8: -123.17011 | G8: =IF(route_map__2[[#This Row],[route_label]]<>A9,0,SQRT((E9-route_map__2[[#This Row],[stop_lat]])^2 + ((F9-route_map__2[[#This Row],[stop_lon]])*COS(RADIANS(route_map__2[[#This Row],[stop_lat]])))^2)*111.32) -> 0.45544053
A9: 002 | B9: 0 | C9: 8 | D9: Northbound Quesnel Dr @ W King Edward Ave | E9: 49.24951 | F9: -123.17167 | G9: =IF(route_map__2[[#This Row],[route_label]]<>A10,0,SQRT((E10-route_map__2[[#This Row],[stop_lat]])^2 + ((F10-route_map__2[[#This Row],[stop_lon]])*COS(RADIANS(route_map__2[[#This Row],[stop_lat]])))^2)*111.32) -> 0.30392194
A10: 002 | B10: 0 | C10: 9 | D10: Northbound Macdonald St @ W King Edward Ave | E10: 49.248517 | F10: -123.16777 | G10: =IF(route_map__2[[#This Row],[route_label]]<>A11,0,SQRT((E11-route_map__2[[#This Row],[stop_lat]])^2 + ((F11-route_map__2[[#This Row],[stop_lon]])*COS(RADIANS(route_map__2[[#This Row],[stop_lat]])))^2)*111.32) -> 0.10445661
A11: 002 | B11: 0 | C11: 10 | D11: Northbound Macdonald St @ Oliver Cres | E11: 49.249455 | F11: -123.16773 | G11: =IF(route_map__2[[#This Row],[route_label]]<>A12,0,SQRT((E12-route_map__2[[#This Row],[stop_lat]])^2 + ((F12-route_map__2[[#This Row],[stop_lon]])*COS(RADIANS(route_map__2[[#This Row],[stop_lat]])))^2)*111.32) -> 0.4045501
A12: 002 | B12: 0 | C12: 11 | D12: Northbound Macdonald St @ W 22 Ave | E12: 49.253089 | F12: -123.16769 | G12: =IF(route_map__2[[#This Row],[route_label]]<>A13,0,SQRT((E13-route_map__2[[#This Row],[stop_lat]])^2 + ((F13-route_map__2[[#This Row],[stop_lon]])*COS(RADIANS(route_map__2[[#This Row],[stop_lat]])))^2)*111.32) -> 0.55726387
A13: 002 | B13: 0 | C13: 12 | D13: Northbound Macdonald St @ W 16 Ave | E13: 49.258079 | F13: -123.1683 | G13: =IF(route_map__2[[#This Row],[route_label]]<>A14,0,SQRT((E14-route_map__2[[#This Row],[stop_lat]])^2 + ((F14-route_map__2[[#This Row],[stop_lon]])*COS(RADIANS(route_map__2[[#This Row],[stop_lat]])))^2)*111.32) -> 0.24761534
... A13323: R6 | B13323: 1 | C13323: 13 | D13323: Newton Exchange @ Bay 5 | E13323: 49.133426 | F13323: -122.84233 | G13323: =IF(route_map__2[[#This Row],[route_label]]<>A13324,0,SQRT((E13324-route_map__2[[#This Row],[stop_lat]])^2 + ((F13324-route_map__2[[#This Row],[stop_lon]])*COS(RADIANS(route_map__2[[#This Row],[stop_lat]])))^2)*111.32) -> 0

Sheet Data Prep
A1: route_short_name | B1: avg_wait_time_minutes | C1: service_span_hours | D1: total_daily_trips | E1: first_bus_departure | F1: last_bus_arrival_excel_ready
A2: 099 | B2: 2.9 | C2: 22 | D2: 451 | E2: 0.22916667 | F2: 0.14513889 | H2: Average City Waiting Time | I2: =AVERAGE(B2:B224) -> 15.841256
A3: R4 | B3: 3.2 | C3: 20.6 | D3: 384 | E3: 0.20833333 | F3: 0.066666667 | H3: Avg City total daily trips | I3: =AVERAGE(D2:D224) -> 102.35874
A4: 049 | B4: 3.6 | C4: 19.6 | D4: 328 | E4: 0.22708333 | F4: 0.04375 | H4: Avg City service hours | I4: =AVERAGE(C2:C224) -> 17.674439
A5: 245 | B5: 4.5 | C5: 20 | D5: 267 | E5: 0.23819444 | F5: 0.070138889 | T5: {=IF(Dashboard!$E$6="","",_xlfn.XLOOKUP(Dashboard!$E$6,_xlfn.ANCHORARRAY(Advanced_Metrics!J2),Advanced_Metrics!K2:K224))} -> 180
A6: R5 | B6: 5 | C6: 21.3 | D6: 258 | E6: 0.20277778 | F6: 0.091666667 | I6: Route Selected | J6: Translink Avg.
A7: R6 | B7: 4.9 | C7: 21.1 | D7: 258 | E7: 0.18680556 | F7: 0.066666667 | H7: Wait times | I7: =IF(Dashboard!E6="","",_xlfn.XLOOKUP(Dashboard!E6,'Data Prep'!A2:A224,'Data Prep'!B2:B224,"")) -> 5 | J7: 15.8
A8: 005 | B8: 5 | C8: 20.9 | D8: 250 | E8: 0.22222222 | F8: 0.09162037 | H8: Service span hours | I8: =IF(Dashboard!E6="","", _xlfn.XLOOKUP(Dashboard!E6,'Data Prep'!A2:A224,'Data Prep'!C2:C224,"")) -> 21.3 | J8: 17.7
A9: 006 | B9: 5 | C9: 20.7 | D9: 250 | E9: 0.22291667 | F9: 0.085416667 | H9: Daily Trips | I9: =IF(Dashboard!E6="","",_xlfn.XLOOKUP(Dashboard!E6,'Data Prep'!A2:A224,'Data Prep'!D2:D224,"")) -> 258 | J9: 102.35874
A10: 130 | B10: 5 | C10: 20.5 | D10: 247 | E10: 0.22569444 | F10: 0.079166667 | H10: Service Hours | I10: =IF(Dashboard!$E$6="", "", TEXT(_xlfn.XLOOKUP(Dashboard!$E$6, 'Data Prep'!A2:A224, 'Data Prep'!E2:E224), "h:mm AM/PM") & " - " & TEXT(_xlfn.XLOOKUP(Dashboard!$E$6, 'Data Prep'!A2:A224, 'Data Prep'!F2:F224), "h:mm AM/PM") & IF(_xlfn.XLOOKUP(Dashboard!$E$6, 'Data Prep'!A2:A224, 'Data Prep'!F2:F224) < _xlfn.XLOOKUP(Dashboard!$E$6, 'Data Prep'!A2:A224, 'Data Prep'!E2:E224), " (Next Day)", "") ) -> 4:52 AM - 2:12 AM (Next Day)
A11: 323 | B11: 5.5 | C11: 22 | D11: 242 | E11: 0.18541667 | F11: 0.10208333 | H11: Average Spacing | I11: =AVERAGEIFS(route_map__2[Distance],route_map__2[route_label],Dashboard!E6,route_map__2[direction_id],1) -> 0.94322909
A12: 009 | B12: 5.6 | C12: 22.2 | D12: 239 | E12: 0.19236111 | F12: 0.11799769 | H12: Service Type | I12: =IF(I11<0.3,"Local Service", IF(I11<0.6,"Urban Route", "Express Service")) -> Express Service
A13: 250 | B13: 5.2 | C13: 20.5 | D13: 238 | E13: 0.21875 | F13: 0.073611111 | R13: =IF(Dashboard!E7="","",_xlfn.XLOOKUP(Dashboard!E7,RiderExperience[route_short_name],RiderExperience[service_span_hours])) | Z13: Distance
A14: 321 | B14: 5.8 | C14: 22.6 | D14: 233 | E14: 0.175 | F14: 0.11666667 | R14: =IF(Dashboard!E8="","",_xlfn.XLOOKUP(Dashboard!E8,RiderExperience[route_short_name],RiderExperience[service_span_hours])) | S14: {=_xlfn.CHOOSECOLS(_xlfn._xlws.FILTER(route_map__2[],(route_map__2[route_label]=Dashboard!E6)*(route_map__2[direction_id]=1),"No Service"), MATCH("stop_lon", route_map__2[#Headers],0), MATCH("stop_lat", route_map__2[#Headers],0),MATCH("stop_name", route_map__2[#Headers],0))} -> -122.91279 | T14: 49.278484 | U14: SFU Transit Exchange @ Bay 2 | Z14: {=_xlfn.CHOOSECOLS(_xlfn._xlws.FILTER(route_map__2[],(route_map__2[route_label]=Dashboard!E6)*(route_map__2[direction_id]=1),"No Service"), MATCH("Distance", route_map__2[#Headers],0))} -> 0.55694172
A15: R1 | B15: 5.5 | C15: 21.1 | D15: 232 | E15: 0.18472222 | F15: 0.064548611 | I15: Route Selected | J15: Morning Peak (6AM - 9AM) | K15: Mid-Day (9AM - 3PM) | L15: Afternoon (3PM - 6:30 PM) | R15: =IF(Dashboard!E9="","",_xlfn.XLOOKUP(Dashboard!E9,RiderExperience[route_short_name],RiderExperience[service_span_hours])) | S15: -122.92012 | T15: 49.279957 | U15: SFU Transportation Centre @ Bay 1 | Z15: 2.462894
A16: 145 | B16: 5.3 | C16: 20.2 | D16: 227 | E16: 0.24097222 | F16: 0.08125 | I16: =Dashboard!E6 -> R5 | J16: {=IF(Dashboard!E6="","",_xlfn.XLOOKUP(Dashboard!E6,_xlfn.ANCHORARRAY(Advanced_Metrics!J2),Advanced_Metrics!K2:K224))} -> 180 | K16: {=IF(Dashboard!E6="","",_xlfn.XLOOKUP(Dashboard!E6,_xlfn.ANCHORARRAY(Advanced_Metrics!J2),Advanced_Metrics!L2:L224))} -> 28 | L16: {=IF(Dashboard!E6="","",_xlfn.XLOOKUP(Dashboard!E6,_xlfn.ANCHORARRAY(Advanced_Metrics!J2),Advanced_Metrics!M2:M224))} -> 50 | R16: =IF(Dashboard!E10="","",_xlfn.XLOOKUP(Dashboard!E10,RiderExperience[route_short_name],RiderExperience[service_span_hours])) | S16: -122.95402 | T16: 49.280475 | U16: Westbound Hastings St @ Duthie Ave | Z16: 1.2039008
A17: 100 | B17: 6.1 | C17: 22.1 | D17: 219 | E17: 0.17708333 | F17: 0.099305556 | R17: =IF(Dashboard!E11="","",_xlfn.XLOOKUP(Dashboard!E11,RiderExperience[route_short_name],RiderExperience[service_span_hours])) | S17: -122.9706 | T17: 49.280464 | U17: Westbound Hastings St @ Kensington Ave | Z17: 0.78561331
A18: 335 | B18: 6.2 | C18: 21.6 | D18: 210 | E18: 0.17916667 | F18: 0.078472222 | R18: =IF(Dashboard!E12="","",_xlfn.XLOOKUP(Dashboard!E12,RiderExperience[route_short_name],RiderExperience[service_span_hours])) | S18: -122.98142 | T18: 49.280436 | U18: Westbound Hastings St @ Holdom Ave | Z18: 0.69698916
A19: 002 | B19: 6.1 | C19: 20.8 | D19: 205 | E19: 0.21527778 | F19: 0.081944444 | R19: =IF(Dashboard!E13="","",_xlfn.XLOOKUP(Dashboard!E13,RiderExperience[route_short_name],RiderExperience[service_span_hours])) | S19: -122.99101 | T19: 49.28024 | U19: Westbound Hastings St @ Hythe Ave | Z19: 0.93752087
A20: 025 | B20: 5.9 | C20: 19.9 | D20: 203 | E20: 0.21597222 | F20: 0.043055556 | R20: =IF(Dashboard!E14="","",_xlfn.XLOOKUP(Dashboard!E14,RiderExperience[route_short_name],RiderExperience[service_span_hours])) | S20: -123.00385 | T20: 49.281121 | U20: Westbound Hastings St @ Willingdon Ave- | Z20: 0.69148752
A21: 106 | B21: 6.4 | C21: 21.7 | D21: 203 | E21: 0.20347222 | F21: 0.10833333 | R21: =IF(Dashboard!E15="","",_xlfn.XLOOKUP(Dashboard!E15,RiderExperience[route_short_name],RiderExperience[service_span_hours])) | S21: -123.01337 | T21: 49.281146 | U21: Westbound Hastings St @ Gilmore Ave | Z21: 0.87283599
A22: 410 | B22: 6.5 | C22: 21.9 | D22: 203 | E22: 0.18263889 | F22: 0.093055556 | R22: =IF(Dashboard!E16="","",_xlfn.XLOOKUP(Dashboard!E16,RiderExperience[route_short_name],RiderExperience[service_span_hours])) | S22: -123.02539 | T22: 49.281204 | U22: Kootenay Loop @ Bay 7 | Z22: 1.3970524
A23: 503 | B23: 6.1 | C23: 20.7 | D23: 202 | E23: 0.18055556 | F23: 0.043055556 | R23: =IF(Dashboard!E17="","",_xlfn.XLOOKUP(Dashboard!E17,RiderExperience[route_short_name],RiderExperience[service_span_hours])) | S23: -123.04463 | T23: 49.281229 | U23: Westbound E Hastings St @ Renfrew St | Z23: 0.91667381
A24: 319 | B24: 6.6 | C24: 22.1 | D24: 200 | E24: 0.18888889 | F24: 0.10763889 | R24: =IF(Dashboard!E18="","",_xlfn.XLOOKUP(Dashboard!E18,RiderExperience[route_short_name],RiderExperience[service_span_hours])) | S24: -123.05725 | T24: 49.281242 | U24: Westbound E Hastings St @ Nanaimo St | Z24: 1.0109478
A25: 023 | B25: 5.6 | C25: 18.5 | D25: 197 | E25: 0.25 | F25: 0.022222222 | R25: =IF(Dashboard!E19="","",_xlfn.XLOOKUP(Dashboard!E19,RiderExperience[route_short_name],RiderExperience[service_span_hours])) | S25: -123.07117 | T25: 49.281362 | U25: Westbound E Hastings St @ Commercial Dr | Z25: 2.0470706
A26: 022 | B26: 6.5 | C26: 21.3 | D26: 197 | E26: 0.20416667 | F26: 0.090972222 | R26: =IF(Dashboard!E20="","",_xlfn.XLOOKUP(Dashboard!E20,RiderExperience[route_short_name],RiderExperience[service_span_hours])) | S26: -123.09936 | T26: 49.281426 | U26: Westbound E Hastings St @ Main St | Z26: 0.54677096
A27: R2 | B27: 6.8 | C27: 21.3 | D27: 189 | E27: 0.21388889 | F27: 0.10208333 | R27: =IF(Dashboard!E21="","",_xlfn.XLOOKUP(Dashboard!E21,RiderExperience[route_short_name],RiderExperience[service_span_hours])) | S27: -123.10684 | T27: 49.282004 | U27: Westbound W Hastings St @ Abbott St | Z27: 0.60808634
A28: 240 | B28: 6.6 | C28: 20.6 | D28: 187 | E28: 0.21180556 | F28: 0.071527778 | R28: =IF(Dashboard!E22="","",_xlfn.XLOOKUP(Dashboard!E22,RiderExperience[route_short_name],RiderExperience[service_span_hours])) | S28: -123.11358 | T28: 49.285242 | U28: Westbound W Hastings St @ Granville St | Z28: 0.35688023
A29: 640 | B29: 6.4 | C29: 19.8 | D29: 185 | E29: 0.1875 | F29: 0.013194444 | R29: =IF(Dashboard!E23="","",_xlfn.XLOOKUP(Dashboard!E23,RiderExperience[route_short_name],RiderExperience[service_span_hours])) | S29: -123.11829 | T29: 49.28616 | U29: Burrard Station @ Bay 6 | Z29: 0
A30: 019 | B30: 7.1 | C30: 21.9 | D30: 184 | E30: 0.20277778 | F30: 0.11458333 | R30: =IF(Dashboard!E24="","",_xlfn.XLOOKUP(Dashboard!E24,RiderExperience[route_short_name],RiderExperience[service_span_hours]))
A31: 123 | B31: 7.2 | C31: 22 | D31: 184 | E31: 0.19444444 | F31: 0.10972222 | R31: =IF(Dashboard!E25="","",_xlfn.XLOOKUP(Dashboard!E25,RiderExperience[route_short_name],RiderExperience[service_span_hours]))
A32: R3 | B32: 6.4 | C32: 19.4 | D32: 181 | E32: 0.20972222 | F32: 0.01875 | R32: =IF(Dashboard!E26="","",_xlfn.XLOOKUP(Dashboard!E26,RiderExperience[route_short_name],RiderExperience[service_span_hours]))
A33: 119 | B33: 7.2 | C33: 21.3 | D33: 177 | E33: 0.21597222 | F33: 0.10277778 | R33: =IF(Dashboard!E27="","",_xlfn.XLOOKUP(Dashboard!E27,RiderExperience[route_short_name],RiderExperience[service_span_hours]))
A34: 020 | B34: 7.4 | C34: 21.8 | D34: 177 | E34: 0.19791667 | F34: 0.10625 | R34: =IF(Dashboard!E28="","",_xlfn.XLOOKUP(Dashboard!E28,RiderExperience[route_short_name],RiderExperience[service_span_hours]))
A35: 502 | B35: 7.6 | C35: 22.4 | D35: 177 | E35: 0.18125 | F35: 0.11319444 | R35: =IF(Dashboard!E29="","",_xlfn.XLOOKUP(Dashboard!E29,RiderExperience[route_short_name],RiderExperience[service_span_hours]))
A36: 016 | B36: 5.8 | C36: 16.7 | D36: 173 | E36: 0.2 | F36: 0.89652778 | R36: =IF(Dashboard!E30="","",_xlfn.XLOOKUP(Dashboard!E30,RiderExperience[route_short_name],RiderExperience[service_span_hours]))
A37: 008 | B37: 7.6 | C37: 21.8 | D37: 171 | E37: 0.20694444 | F37: 0.11319444 | R37: =IF(Dashboard!E31="","",_xlfn.XLOOKUP(Dashboard!E31,RiderExperience[route_short_name],RiderExperience[service_span_hours]))
A38: 406 | B38: 7.6 | C38: 21.5 | D38: 170 | E38: 0.19236111 | F38: 0.0875 | R38: =IF(Dashboard!E32="","",_xlfn.XLOOKUP(Dashboard!E32,RiderExperience[route_short_name],RiderExperience[service_span_hours]))
A39: 003 | B39: 7.7 | C39: 21.7 | D39: 170 | E39: 0.20138889 | F39: 0.10694444 | R39: =IF(Dashboard!E33="","",_xlfn.XLOOKUP(Dashboard!E33,RiderExperience[route_short_name],RiderExperience[service_span_hours]))
A40: 041 | B40: 8.3 | C40: 22.9 | D40: 166 | E40: 0.17430556 | F40: 0.12638889 | R40: =IF(Dashboard!E34="","",_xlfn.XLOOKUP(Dashboard!E34,RiderExperience[route_short_name],RiderExperience[service_span_hours]))
...

Sheet Dashboard
C6: Select Route | E6: R5 | G6: =IF(E6="","",_xlfn.XLOOKUP(E6,RiderExperience[route_short_name],RiderExperience[route_long_name],"")) -> Hastings St
